Workbook
Name MAX_RISK: Inputs!$B$9
Name MODAL_AWAL: Inputs!$B$6
Name RR_RATIO: Inputs!$B$10
Name TARGET_BESAR: Inputs!$B$8
Name TARGET_GROWTH_BULAN: Inputs!$B$7

Sheet Inputs
A1: SUPER TEMPLATE: Money Management Sakti — Inputs
A3: Deskripsi
A4: Isi parameter utama di sini. Ubah angka untuk menyesuaikan rencana Anda.
A6: Modal Awal (Rp) | B6: 10000000
A7: Target Pertumbuhan Bulanan (kompound) | B7: 0.1
A8: Target Besar (Rp) | B8: 1000000000
A9: Max Risk per Trade (% dari modal) | B9: 0.01
A10: Risk / Reward Ratio | B10: 2
A12: Catatan:
A13: • Semua sheet terhubung ke angka di atas. • Dashboard akan menyesuaikan otomatis. • Ubah hanya sel di kolom B (biru) pada sheet Inputs.

Sheet RiskManagement
A1: Risk Management Master
A3: Modal Saat Ini | B3: =MODAL_AWAL
A4: Max Risk per Trade (%) | B4: =MAX_RISK
A5: Risk / Reward Ratio | B5: =RR_RATIO
A7: Risk Amount per Trade (Rp) | B7: =B3*B4
A8: Target Profit per Trade (Rp) | B8: =B7*B5
A10: Kalkulator Position Size (contoh saham)
A11: Harga Entry | B11: 5000
A12: Stop Loss (Harga) | B12: 4850
A13: Risiko per Lembar (Entry - SL) | B13: =B11-B12
A14: Ukuran Posisi (lembar) | B14: =IF(B13>0,ROUND(B7/B13,0),0)
A16: Catatan:
A17: • Ganti 'Harga Entry' dan 'Stop Loss' sesuai instrumen. • Untuk forex/kripto, sesuaikan unit & ukuran kontrak. • Jaga risk per trade ≤ 1–2%.

Sheet MonthlyRoadmap
A1: Monthly Roadmap ke Rp 2 Miliar (Compound)
A3: Bulan | B3: Target Growth | C3: Target Saldo Awal | D3: Target Saldo Akhir | E3: Checklist | G3: Perkiraan Bulan Mencapai Target | H3: =MATCH(TARGET_BESAR, D4:D123, 1)+1
A4: 1 | B4: =TARGET_GROWTH_BULAN | C4: =MODAL_AWAL | D4: =C4*(1+B4) | G4: Catatan
A5: 2 | B5: =TARGET_GROWTH_BULAN | C5: =D4 | D5: =C5*(1+B5) | G5: Nilai di atas menggunakan MATCH mode approximate (1) pada deret meningkat. Jika Hasil #N/A, target belum tercapai dalam 120 bulan.
A6: 3 | B6: =TARGET_GROWTH_BULAN | C6: =D5 | D6: =C6*(1+B6)
A7: 4 | B7: =TARGET_GROWTH_BULAN | C7: =D6 | D7: =C7*(1+B7)
A8: 5 | B8: =TARGET_GROWTH_BULAN | C8: =D7 | D8: =C8*(1+B8)
A9: 6 | B9: =TARGET_GROWTH_BULAN | C9: =D8 | D9: =C9*(1+B9)
A10: 7 | B10: =TARGET_GROWTH_BULAN | C10: =D9 | D10: =C10*(1+B10)
A11: 8 | B11: =TARGET_GROWTH_BULAN | C11: =D10 | D11: =C11*(1+B11)
A12: 9 | B12: =TARGET_GROWTH_BULAN | C12: =D11 | D12: =C12*(1+B12)
A13: 10 | B13: =TARGET_GROWTH_BULAN | C13: =D12 | D13: =C13*(1+B13)
A14: 11 | B14: =TARGET_GROWTH_BULAN | C14: =D13 | D14: =C14*(1+B14)
A15: 12 | B15: =TARGET_GROWTH_BULAN | C15: =D14 | D15: =C15*(1+B15)
A16: 13 | B16: =TARGET_GROWTH_BULAN | C16: =D15 | D16: =C16*(1+B16)
A17: 14 | B17: =TARGET_GROWTH_BULAN | C17: =D16 | D17: =C17*(1+B17)
... A123: 120 | B123: =TARGET_GROWTH_BULAN | C123: =D122 | D123: =C123*(1+B123)

Sheet TradeJournal
A1: Trade Journal Sakti
A3: Tanggal | B3: Instrumen | C3: Entry | D3: StopLoss | E3: TakeProfit | F3: Lot/Qty | G3: Risk % | H3: Hasil P/L | I3: R Multiple | J3: Emosi/Catatan | K3: Screenshot Link | M3: Summary
I4: =_xlfn.IFERROR(H4/RiskManagement!$B$7,0) | M4: Total Trades | N4: =COUNTA(A4:A103)
I5: =_xlfn.IFERROR(H5/RiskManagement!$B$7,0) | M5: Win Trades | N5: =COUNTIF(H4:H103,">0")
I6: =_xlfn.IFERROR(H6/RiskManagement!$B$7,0) | M6: Lose Trades | N6: =COUNTIF(H4:H103,"<0")
I7: =_xlfn.IFERROR(H7/RiskManagement!$B$7,0) | M7: Win Rate | N7: =_xlfn.IFERROR(N5/N4,0)
I8: =_xlfn.IFERROR(H8/RiskManagement!$B$7,0) | M8: Average R:R (avg R multiple wins) | N8: =_xlfn.IFERROR(AVERAGEIF(I4:I103,">0"),0)
I9: =_xlfn.IFERROR(H9/RiskManagement!$B$7,0) | M9: Total P/L | N9: =SUM(H4:H103)
I10: =_xlfn.IFERROR(H10/RiskManagement!$B$7,0)
I11: =_xlfn.IFERROR(H11/RiskManagement!$B$7,0)
I12: =_xlfn.IFERROR(H12/RiskManagement!$B$7,0)
I13: =_xlfn.IFERROR(H13/RiskManagement!$B$7,0)
I14: =_xlfn.IFERROR(H14/RiskManagement!$B$7,0)
I15: =_xlfn.IFERROR(H15/RiskManagement!$B$7,0)
I16: =_xlfn.IFERROR(H16/RiskManagement!$B$7,0)
I17: =_xlfn.IFERROR(H17/RiskManagement!$B$7,0)
I18: =_xlfn.IFERROR(H18/RiskManagement!$B$7,0)
I19: =_xlfn.IFERROR(H19/RiskManagement!$B$7,0)
I20: =_xlfn.IFERROR(H20/RiskManagement!$B$7,0)
I21: =_xlfn.IFERROR(H21/RiskManagement!$B$7,0)
... I103: =_xlfn.IFERROR(H103/RiskManagement!$B$7,0)

Sheet ScenarioPlanner
A1: Scenario Planner — Berapa Lama ke Rp 2 Miliar?
A3: Skenario | B3: Growth Bulanan | C3: Bulan ke- | D3: Proyeksi Saldo
A4: Konservatif | B4: 0.05 | C4: =ROUNDUP(LN(TARGET_BESAR/MODAL_AWAL)/LN(1+B4),0) | D4: =MODAL_AWAL*(1+B4)^C4
A5: Moderate | B5: 0.1 | C5: =ROUNDUP(LN(TARGET_BESAR/MODAL_AWAL)/LN(1+B5),0) | D5: =MODAL_AWAL*(1+B5)^C5
A6: Agresif | B6: 0.15 | C6: =ROUNDUP(LN(TARGET_BESAR/MODAL_AWAL)/LN(1+B6),0) | D6: =MODAL_AWAL*(1+B6)^C6

Sheet Warnings
A1: Warning System (Anti Margin Call)
A3: Risk per Trade melebihi 2%? | B3: =IF(MAX_RISK>0.02,"YA","AMAN")
A4: Loss beruntun (isi manual) | B4: 0
A5: Batas Loss Beruntun (disarankan 5) | B5: 5
A7: Status | B7: =IF(OR(B3="YA",B4>=B5),"PERINGATAN: Stop trading & evaluasi dulu","OK: Lanjut sesuai plan")
A9: Tips:
A10: • Jaga risk per trade ≤ 2%. • Jika kena 5x loss beruntun, berhenti sementara & evaluasi. • Hindari overtrade dan revenge trade. • Ikuti plan dan disiplin.

Sheet Affirmations
A1: Daily Affirmation — Mindset Trader Sakti
A3: Checklist Harian:
A5: ☐ Saya disiplin mengikuti trading plan.
A6: ☐ Saya menerima loss kecil untuk menghindari loss besar.
A7: ☐ Saya tidak balas dendam pada market.
A8: ☐ Saya trading hanya saat setup A+ sesuai strategi.
A9: ☐ Profit besar adalah hasil konsistensi jangka panjang.

Sheet Dashboard
A1: DASHBOARD — Money Management Sakti (Rp2 Miliar Roadmap)
A3: Modal Awal | B3: =MODAL_AWAL | D3: =MonthlyRoadmap!A4 | E3: =MonthlyRoadmap!D4
A4: Target Bulanan (Growth) | B4: =TARGET_GROWTH_BULAN | D4: =MonthlyRoadmap!A5 | E4: =MonthlyRoadmap!D5
A5: Target Besar | B5: =TARGET_BESAR | D5: =MonthlyRoadmap!A6 | E5: =MonthlyRoadmap!D6
D6: =MonthlyRoadmap!A7 | E6: =MonthlyRoadmap!D7
A7: Perkiraan Bulan Mencapai Target (berdasarkan roadmap) | B7: =MonthlyRoadmap!H3 | D7: =MonthlyRoadmap!A8 | E7: =MonthlyRoadmap!D8
D8: =MonthlyRoadmap!A9 | E8: =MonthlyRoadmap!D9
A9: Progress % ke Target (berdasarkan saldo roadmap bulan terakhir) | B9: =MonthlyRoadmap!D123/TARGET_BESAR | D9: =MonthlyRoadmap!A10 | E9: =MonthlyRoadmap!D10
D10: =MonthlyRoadmap!A11 | E10: =MonthlyRoadmap!D11
A11: Grafik Pertumbuhan Modal (hingga 120 bulan) | D11: =MonthlyRoadmap!A12 | E11: =MonthlyRoadmap!D12
D12: =MonthlyRoadmap!A13 | E12: =MonthlyRoadmap!D13
D13: =MonthlyRoadmap!A14 | E13: =MonthlyRoadmap!D14
D14: =MonthlyRoadmap!A15 | E14: =MonthlyRoadmap!D15
D15: =MonthlyRoadmap!A16 | E15: =MonthlyRoadmap!D16
D16: =MonthlyRoadmap!A17 | E16: =MonthlyRoadmap!D17
D17: =MonthlyRoadmap!A18 | E17: =MonthlyRoadmap!D18
D18: =MonthlyRoadmap!A19 | E18: =MonthlyRoadmap!D19
D19: =MonthlyRoadmap!A20 | E19: =MonthlyRoadmap!D20
D20: =MonthlyRoadmap!A21 | E20: =MonthlyRoadmap!D21
D21: =MonthlyRoadmap!A22 | E21: =MonthlyRoadmap!D22
D22: =MonthlyRoadmap!A23 | E22: =MonthlyRoadmap!D23
D23: =MonthlyRoadmap!A24 | E23: =MonthlyRoadmap!D24
... D30: =MonthlyRoadmap!A31 | E30: =MonthlyRoadmap!D31
A31: Cara Pakai Singkat: | D31: =MonthlyRoadmap!A32 | E31: =MonthlyRoadmap!D32
A32: 1) Buka sheet Inputs, isi modal, growth bulanan, risk, dll. 2) Cek Dashboard untuk melihat progress & perkiraan bulan capai target. 3) Catat semua transaksi di TradeJournal. 4) Gunakan RiskManagement untuk hitung lot, SL, TP. 5) Pantau Warnings saat risk kebablasan. | D32: =MonthlyRoadmap!A33 | E32: =MonthlyRoadmap!D33
D33: =MonthlyRoadmap!A34 | E33: =MonthlyRoadmap!D34
D34: =MonthlyRoadmap!A35 | E34: =MonthlyRoadmap!D35
D35: =MonthlyRoadmap!A36 | E35: =MonthlyRoadmap!D36
A36: Template dibuat: 2025-09-19 03:37:27 | D36: =MonthlyRoadmap!A37 | E36: =MonthlyRoadmap!D37
D37: =MonthlyRoadmap!A38 | E37: =MonthlyRoadmap!D38
D38: =MonthlyRoadmap!A39 | E38: =MonthlyRoadmap!D39
D39: =MonthlyRoadmap!A40 | E39: =MonthlyRoadmap!D40
D40: =MonthlyRoadmap!A41 | E40: =MonthlyRoadmap!D41
D41: =MonthlyRoadmap!A42 | E41: =MonthlyRoadmap!D42
D42: =MonthlyRoadmap!A43 | E42: =MonthlyRoadmap!D43
D43: =MonthlyRoadmap!A44 | E43: =MonthlyRoadmap!D44
D44: =MonthlyRoadmap!A45 | E44: =MonthlyRoadmap!D45
D45: =MonthlyRoadmap!A46 | E45: =MonthlyRoadmap!D46
D46: =MonthlyRoadmap!A47 | E46: =MonthlyRoadmap!D47
D47: =MonthlyRoadmap!A48 | E47: =MonthlyRoadmap!D48
...
